<?xml version="1.0" ?>
<!-- =================================================================================== -->
<!-- |    This document was autogenerated by xacro from diffbot_4wheel.xacro           | -->
<!-- |    EDITING THIS FILE BY HAND IS NOT RECOMMENDED                                 | -->
<!-- =================================================================================== -->
<robot name="diffbot_4wheel">
  <!--Base Footprint-->
  <link name="base_footprint"/>
  <joint name="base_footprint_to_base_link" type="fixed">
    <parent link="base_footprint"/>
    <child link="base_link"/>
    <origin rpy="0 0 0" xyz="0 0 0.02675"/>
    <axis xyz="0 0 0"/>
  </joint>
  <!--Base Link-->
  <link name="base_link">
    <pose>0 0 0.1    0 0 0</pose>
    <!--Where to place robot in Gazebo-->
    <inertial>
      <mass value="25"/>
      <inertia ixx="0.05837889615885416" ixy="0" ixz="0" iyy="0.02332194596354166" iyz="0" izz="0.07160971647135417"/>
    </inertial>
    <collision name="base_link_collision">
      <origin rpy="0 0 0" xyz="0 0 0"/>
      <geometry>
        <box size="0.16 0.0936625 0.0492125"/>
      </geometry>
    </collision>
    <visual>
      <origin rpy="0 0 0" xyz="0 0 0"/>
      <geometry>
        <box size="0.16 0.0936625 0.0492125"/>
      </geometry>
      <material name="bright_green">
        <color rgba="0 1 0 1"/>
      </material>
    </visual>
  </link>
  <gazebo reference="base_link">
    <material>Gazebo/Green</material>
  </gazebo>
  <!--Front Right Wheel-->
  <link name="front_right_wheel">
    <!--True inertial measurements for wheels are too small, so they're substituted with 0.1-->
    <inertial>
      <mass value="0.1"/>
      <inertia ixx="0.1" ixy="0" ixz="0" iyy="0.1" iyz="0" izz="0.1"/>
    </inertial>
    <collision>
      <origin rpy="0 0 0" xyz="0 0 0"/>
      <geometry>
        <cylinder length="0.0127" radius="0.02175"/>
      </geometry>
    </collision>
    <visual>
      <origin rpy="0 0 0" xyz="0 0 0"/>
      <geometry>
        <cylinder length="0.0127" radius="0.02175"/>
      </geometry>
      <material name="black">
        <color rgba="0 0 0 1"/>
      </material>
    </visual>
  </link>
  <joint name="joint_front_right_wheel" type="continuous">
    <parent link="base_link"/>
    <child link="front_right_wheel"/>
    <origin rpy="1.5707963267948966 0 0" xyz="0.06175 -0.05318125 -0.01"/>
    <axis xyz="0 0 -1"/>
    <limit effort="10000" velocity="1000"/>
    <dynamics damping="1.0" friction="1.0"/>
  </joint>
  <gazebo reference="front_right_wheel">
    <material>Gazebo/Black</material>
  </gazebo>
  <!--Front Left Wheel-->
  <link name="front_left_wheel">
    <!--True inertial measurements for wheels are too small, so they're substituted with 0.1-->
    <inertial>
      <mass value="0.1"/>
      <inertia ixx="0.1" ixy="0" ixz="0" iyy="0.1" iyz="0" izz="0.1"/>
    </inertial>
    <collision>
      <origin rpy="0 0 0" xyz="0 0 0"/>
      <geometry>
        <cylinder length="0.0127" radius="0.02175"/>
      </geometry>
    </collision>
    <visual>
      <origin rpy="0 0 0" xyz="0 0 0"/>
      <geometry>
        <cylinder length="0.0127" radius="0.02175"/>
      </geometry>
      <material name="black">
        <color rgba="0 0 0 1"/>
      </material>
    </visual>
  </link>
  <joint name="joint_front_left_wheel" type="continuous">
    <parent link="base_link"/>
    <child link="front_left_wheel"/>
    <origin rpy="-1.5707963267948966 0 0" xyz="0.06175 0.05318125 -0.01"/>
    <axis xyz="0 0 1"/>
    <limit effort="10000" velocity="1000"/>
    <dynamics damping="1.0" friction="1.0"/>
  </joint>
  <gazebo reference="front_left_wheel">
    <material>Gazebo/Black</material>
  </gazebo>
  <!--Back Right Wheel-->
  <link name="back_right_wheel">
    <!--True inertial measurements for wheels are too small, so they're substituted with 0.1-->
    <inertial>
      <mass value="0.1"/>
      <inertia ixx="0.1" ixy="0" ixz="0" iyy="0.1" iyz="0" izz="0.1"/>
    </inertial>
    <collision>
      <origin rpy="0 0 0" xyz="0 0 0"/>
      <geometry>
        <cylinder length="0.0127" radius="0.02175"/>
      </geometry>
    </collision>
    <visual>
      <origin rpy="0 0 0" xyz="0 0 0"/>
      <geometry>
        <cylinder length="0.0127" radius="0.02175"/>
      </geometry>
      <material name="black">
        <color rgba="0 0 0 1"/>
      </material>
    </visual>
  </link>
  <joint name="joint_back_right_wheel" type="continuous">
    <parent link="base_link"/>
    <child link="back_right_wheel"/>
    <origin rpy="1.5707963267948966 0 0" xyz="-0.06175 -0.05318125 -0.01"/>
    <axis xyz="0 0 -1"/>
    <limit effort="10000" velocity="1000"/>
    <dynamics damping="1.0" friction="1.0"/>
  </joint>
  <gazebo reference="back_right_wheel">
    <material>Gazebo/Black</material>
  </gazebo>
  <!--Back Left Wheel-->
  <link name="back_left_wheel">
    <!--True inertial measurements for wheels are too small, so they're substituted with 0.1-->
    <inertial>
      <mass value="0.1"/>
      <inertia ixx="0.1" ixy="0" ixz="0" iyy="0.1" iyz="0" izz="0.1"/>
    </inertial>
    <collision>
      <origin rpy="0 0 0" xyz="0 0 0"/>
      <geometry>
        <cylinder length="0.0127" radius="0.02175"/>
      </geometry>
    </collision>
    <visual>
      <origin rpy="0 0 0" xyz="0 0 0"/>
      <geometry>
        <cylinder length="0.0127" radius="0.02175"/>
      </geometry>
      <material name="black">
        <color rgba="0 0 0 1"/>
      </material>
    </visual>
  </link>
  <joint name="joint_back_left_wheel" type="continuous">
    <parent link="base_link"/>
    <child link="back_left_wheel"/>
    <origin rpy="-1.5707963267948966 0 0" xyz="-0.06175 0.05318125 -0.01"/>
    <axis xyz="0 0 1"/>
    <limit effort="10000" velocity="1000"/>
    <dynamics damping="1.0" friction="1.0"/>
  </joint>
  <gazebo reference="back_left_wheel">
    <material>Gazebo/Black</material>
  </gazebo>
  <!-- Hokuyo Laser -->
  <link name="hokuyo_link">
    <collision>
      <origin rpy="0 0 0" xyz="0 0 0"/>
      <geometry>
        <box size="0.1 0.1 0.1"/>
      </geometry>
    </collision>
    <visual>
      <origin rpy="0 0 0" xyz="0 0 0"/>
      <geometry>
        <!--Mesh obtained from  https://github.com/ros-simulation/gazebo_ros_demos-->
        <mesh filename="package://diffbot_1/meshes/hokuyo.dae"/>
      </geometry>
    </visual>
    <inertial>
      <mass value="1e-5"/>
      <origin rpy="0 0 0" xyz="0 0 0"/>
      <inertia ixx="1e-6" ixy="0" ixz="0" iyy="1e-6" iyz="0" izz="1e-6"/>
    </inertial>
  </link>
  <joint name="hokuyo_joint" type="fixed">
    <axis xyz="0 1 0"/>
    <origin rpy="0 0 0" xyz="0 0 0.0492125"/>
    <parent link="base_link"/>
    <child link="hokuyo_link"/>
  </joint>
  <!-- Gazebo Hokuyo -->
  <gazebo reference="hokuyo_link">
    <sensor name="head_hokuyo_sensor" type="ray">
      <pose>0 0 0 0 0 0</pose>
      <visualize>true</visualize>
      <update_rate>40</update_rate>
      <ray>
        <scan>
          <horizontal>
            <samples>720</samples>
            <resolution>1</resolution>
            <min_angle>-1.570796</min_angle>
            <max_angle>1.570796</max_angle>
          </horizontal>
        </scan>
        <range>
          <min>0.10</min>
          <max>30.0</max>
          <resolution>0.01</resolution>
        </range>
        <noise>
          <type>gaussian</type>
          <!-- Noise parameters based on published spec for Hokuyo laser achieving 
                        "+-30mm" accuracy at range < 10m. A mean of 0.0m and stddev of 0.01m will 
                        put 99.7% of samples within 0.03m of the true reading. -->
          <mean>0.0</mean>
          <stddev>0.01</stddev>
        </noise>
      </ray>
      <plugin filename="libgazebo_ros_laser.so" name="gazebo_ros_head_hokuyo_controller">
        <topicName>/rrbot/laser/scan</topicName>
        <frameName>hokuyo_link</frameName>
      </plugin>
    </sensor>
  </gazebo>
  <!--Gazebo Plugin-->
  <gazebo>
    <plugin filename="libgazebo_ros_skid_steer_drive.so" name="skid_steer_drive_controller">
      <updateRate>10.0</updateRate>
      <robotNamespace>/</robotNamespace>
      <leftFrontJoint>joint_front_left_wheel</leftFrontJoint>
      <rightFrontJoint>joint_front_right_wheel</rightFrontJoint>
      <leftRearJoint>joint_back_left_wheel</leftRearJoint>
      <rightRearJoint>joint_back_right_wheel</rightRearJoint>
      <wheelSeparation>0.0936625</wheelSeparation>
      <wheelDiameter>0.0635</wheelDiameter>
      <torque>2.5</torque>
      <robotBaseFrame>base_footprint</robotBaseFrame>
      <topicName>cmd_vel</topicName>
      <commandTopic>cmd_vel</commandTopic>
      <odometryTopic>odom</odometryTopic>
      <odometryFrame>odom</odometryFrame>
      <broadcastTF>true</broadcastTF>
      <topic_name_twist>cmd_vel</topic_name_twist>
      <topic_name_odometry>odom</topic_name_odometry>
      <covariance_x>0.0001</covariance_x>
      <covariance_y>0.0001</covariance_y>
      <covariance_yaw>0.01</covariance_yaw>
    </plugin>
  </gazebo>
</robot>

